<?xml version="1.0" encoding="utf-8"?>
<!-- This URDF was automatically created by SolidWorks to URDF Exporter! Originally created by Stephen Brawner (brawner@gmail.com) 
     Commit Version: 1.5.0-0-g9aa0fdb  Build Version: 1.5.7004.21443
     For more information, please see http://wiki.ros.org/sw_urdf_exporter -->
<robot
  name="tricycle">
  <link
    name="base_link">
    <inertial>
      <origin
        xyz="-0.0033726 8.74E-19 -9.1444E-19"
        rpy="0 0 0" />
      <mass
        value="0.019875" />
      <inertia
        ixx="3.2883E-06"
        ixy="-2.6326E-22"
        ixz="8.5251E-23"
        iyy="5.7903E-06"
        iyz="-1.683E-23"
        izz="8.7474E-06" />
    </inertial>
    <visual>
      <origin
        xyz="0 0 0"
        rpy="0 0 0" />
      <geometry>
        <mesh
          filename="package://tricycle/meshes/base_link.STL" />
      </geometry>
      <material
        name="">
        <color
          rgba="0.79216 0.81961 0.93333 1" />
      </material>
    </visual>
    <collision>
      <origin
        xyz="0 0 0"
        rpy="0 0 0" />
      <geometry>
        <mesh
          filename="package://tricycle/meshes/base_link.STL" />
      </geometry>
    </collision>
  </link>
  <link
    name="front_wheel_link">
    <inertial>
      <origin
        xyz="-0.005 1.5073E-17 -6.9389E-18"
        rpy="0 0 0" />
      <mass
        value="0.0012229" />
      <inertia
        ixx="1.4325E-08"
        ixy="6.4934E-25"
        ixz="4.9199E-24"
        iyy="1.7354E-08"
        iyz="5.8937E-24"
        izz="1.7354E-08" />
    </inertial>
    <visual>
      <origin
        xyz="0 0 0"
        rpy="0 0 0" />
      <geometry>
        <mesh
          filename="package://tricycle/meshes/front_wheel_link.STL" />
      </geometry>
      <material
        name="">
        <color
          rgba="0.79216 0.81961 0.93333 1" />
      </material>
    </visual>
    <collision>
      <origin
        xyz="0 0 0"
        rpy="0 0 0" />
      <geometry>
        <mesh
          filename="package://tricycle/meshes/front_wheel_link.STL" />
      </geometry>
    </collision>
  </link>
  <joint
    name="front_wheel_joint"
    type="continuous">
    <origin
      xyz="0.02 -0.005 0"
      rpy="1.5708 0 -1.5708" />
    <parent
      link="base_link" />
    <child
      link="front_wheel_link" />
    <axis
      xyz="-1 0 0" />
    <safety_controller
      k_velocity="0" />
  </joint>
  <link
    name="rear_right_wheel_link">
    <inertial>
      <origin
        xyz="-0.005 1.4199E-17 0"
        rpy="0 0 0" />
      <mass
        value="0.0012229" />
      <inertia
        ixx="1.4325E-08"
        ixy="-6.575E-25"
        ixz="-1.7066E-24"
        iyy="1.7354E-08"
        iyz="1.675E-23"
        izz="1.7354E-08" />
    </inertial>
    <visual>
      <origin
        xyz="0 0 0"
        rpy="0 0 0" />
      <geometry>
        <mesh
          filename="package://tricycle/meshes/rear_right_wheel_link.STL" />
      </geometry>
      <material
        name="">
        <color
          rgba="0.79216 0.81961 0.93333 1" />
      </material>
    </visual>
    <collision>
      <origin
        xyz="0 0 0"
        rpy="0 0 0" />
      <geometry>
        <mesh
          filename="package://tricycle/meshes/rear_right_wheel_link.STL" />
      </geometry>
    </collision>
  </link>
  <joint
    name="rear_right_wheel_joint"
    type="continuous">
    <origin
      xyz="-0.02 -0.03 0"
      rpy="1.5708 0 -1.5708" />
    <parent
      link="base_link" />
    <child
      link="rear_right_wheel_link" />
    <axis
      xyz="-1 0 0" />
    <safety_controller
      k_velocity="0" />
  </joint>
  <link
    name="rear_left_wheel_link">
    <inertial>
      <origin
        xyz="-0.005 3.0191E-18 -1.3878E-17"
        rpy="0 0 0" />
      <mass
        value="0.0012229" />
      <inertia
        ixx="1.4325E-08"
        ixy="-2.2512E-24"
        ixz="-1.8331E-25"
        iyy="1.7354E-08"
        iyz="-4.1101E-23"
        izz="1.7354E-08" />
    </inertial>
    <visual>
      <origin
        xyz="0 0 0"
        rpy="0 0 0" />
      <geometry>
        <mesh
          filename="package://tricycle/meshes/rear_left_wheel_link.STL" />
      </geometry>
      <material
        name="">
        <color
          rgba="0.79216 0.81961 0.93333 1" />
      </material>
    </visual>
    <collision>
      <origin
        xyz="0 0 0"
        rpy="0 0 0" />
      <geometry>
        <mesh
          filename="package://tricycle/meshes/rear_left_wheel_link.STL" />
      </geometry>
    </collision>
  </link>
  <joint
    name="rear_left_wheel_joint"
    type="continuous">
    <origin
      xyz="-0.02 0.03 0"
      rpy="1.5708 0 1.5708" />
    <parent
      link="base_link" />
    <child
      link="rear_left_wheel_link" />
    <axis
      xyz="1 0 0" />
    <safety_controller
      k_velocity="0" />
  </joint>
</robot>