<?xml version="1.0" encoding="utf-8"?>
<!-- This URDF was automatically created by SolidWorks to URDF Exporter! Originally created by Stephen Brawner (brawner@gmail.com) 
     Commit Version: 1.5.1-0-g916b5db  Build Version: 1.5.7152.31018
     For more information, please see http://wiki.ros.org/sw_urdf_exporter -->
<robot
  name="simple_robot">
  <link
    name="base_link">
    <inertial>
      <origin
        xyz="1.4745E-17 0.042753 0.0014737"
        rpy="0 0 0" />
      <mass
        value="1" />
      <inertia
        ixx="0.00032204"
        ixy="-2.1108E-20"
        ixz="5.3975E-22"
        iyy="0.0001277"
        iyz="8.4706E-06"
        izz="0.00044301" />
    </inertial>
    <visual>
      <origin
        xyz="0 0 0"
        rpy="0 0 0" />
      <geometry>
        <mesh
          filename="package://simple_robot/meshes/base_link.STL" />
      </geometry>
      <material
        name="">
        <color
          rgba="0.79216 0.81961 0.93333 1" />
      </material>
    </visual>
    <collision>
      <origin
        xyz="0 0 0"
        rpy="0 0 0" />
      <geometry>
        <mesh
          filename="package://simple_robot/meshes/base_link.STL" />
      </geometry>
    </collision>
  </link>
  <link
    name="R_Link">
    <inertial>
      <origin
        xyz="0 -0.005 0"
        rpy="0 0 0" />
      <mass
        value="0.1" />
      <inertia
        ixx="3.2296E-06"
        ixy="-5.9881E-39"
        ixz="2.0404E-37"
        iyy="6.1353E-06"
        iyz="4.108E-22"
        izz="3.2296E-06" />
    </inertial>
    <visual>
      <origin
        xyz="0 0 0"
        rpy="0 0 0" />
      <geometry>
        <mesh
          filename="package://simple_robot/meshes/R_Link.STL" />
      </geometry>
      <material
        name="">
        <color
          rgba="0.79216 0.81961 0.93333 1" />
      </material>
    </visual>
    <collision>
      <origin
        xyz="0 0 0"
        rpy="0 0 0" />
      <geometry>
        <mesh
          filename="package://simple_robot/meshes/R_Link.STL" />
      </geometry>
    </collision>
  </link>
  <joint
    name="joint_R"
    type="continuous">
    <origin
      xyz="-0.051 0 0.0025"
      rpy="1.5708 1.5708 0" />
    <parent
      link="base_link" />
    <child
      link="R_Link" />
    <axis
      xyz="0 1 0" />
  </joint>
  <link
    name="L_Link">
    <inertial>
      <origin
        xyz="0 0.005 2.7756E-17"
        rpy="0 0 0" />
      <mass
        value="0.1" />
      <inertia
        ixx="3.2296E-06"
        ixy="-4.2967E-38"
        ixz="1.3256E-37"
        iyy="6.1353E-06"
        iyz="4.1135E-22"
        izz="3.2296E-06" />
    </inertial>
    <visual>
      <origin
        xyz="0 0 0"
        rpy="0 0 0" />
      <geometry>
        <mesh
          filename="package://simple_robot/meshes/L_Link.STL" />
      </geometry>
      <material
        name="">
        <color
          rgba="0.79216 0.81961 0.93333 1" />
      </material>
    </visual>
    <collision>
      <origin
        xyz="0 0 0"
        rpy="0 0 0" />
      <geometry>
        <mesh
          filename="package://simple_robot/meshes/L_Link.STL" />
      </geometry>
    </collision>
  </link>
  <joint
    name="joint_L"
    type="continuous">
    <origin
      xyz="0.051 0 0.0025"
      rpy="1.5708 1.5708 0" />
    <parent
      link="base_link" />
    <child
      link="L_Link" />
    <axis
      xyz="0 1 0" />
  </joint>
</robot>