<?xml version="1.0"?>
<robot name="simple_example">

<gazebo>
  <plugin name="gazebo_ros_control" filename="libgazebo_ros_control.so">
    <robotNamespace>/simple_model</robotNamespace>
    <robotSimType>gazebo_ros_control/DefaultRobotHWSim</robotSimType>
    <legacyModeNS>true</legacyModeNS>
  </plugin>
</gazebo>

<link name="dummy_link">
</link>

<link name="base_link">
  <inertial>
    <mass value="10"/>
    <inertia ixx="0.4" ixy="0.0" ixz="0.0" iyy="0.4" iyz="0.0" izz="0.2"/>
  </inertial>
  <collision>
    <geometry>
      <cylinder radius="0.05" length="0.24"/>
    </geometry>
  </collision>
  <visual>
    <geometry>
      <cylinder radius="0.05" length="0.24"/>
    </geometry>
  </visual>
</link>

<joint name="dummy_base_joint" type="fixed">
  <parent link="dummy_link"/>
  <child link="base_link"/>
</joint>

<link name="second_link">
  <inertial>
    <mass value="0.18"/>
    <inertia ixx="0.0002835" ixy="0.0" ixz="0.0" iyy="0.0002835" iyz="0.0" izz="0.000324"/>
  </inertial>
  <origin rpy="0.0 0.0 0.0" xyz="0.0 0.0 0.0"/>
  <collision>
    <geometry>
      <box size="0.05 0.05 0.15"/>
    </geometry>
  </collision>
  <visual>
    <geometry>
      <box size="0.05 0.05 0.15"/>
    </geometry>
  </visual>
</link>

<joint name="base_to_second_joint" type="continuous">
  <parent link="base_link"/>
  <child link="second_link"/>
  <axis xyz="1 0 0"/>
  <origin xyz="0.0 0.0 0.2" rpy="0.0 0.0 0.0"/> 
</joint>

<transmission name="trans1">
  <type>transmission_interface/SimpleTransmission</type>
  <joint name="base_to_second_joint">
    <hardwareInterface>hardware_interface/EffortJointInterface</hardwareInterface>
  </joint>
  <actuator name="motor1">
    <hardwareInterface>hardware_interface/EffortJointInterface</hardwareInterface>
    <mechanicalReduction>1</mechanicalReduction>
  </actuator>
</transmission>

</robot>