<robot name="naro">

    <material name="blue">
        <color rgba="0 0 0.8 1"/>
    </material>
    <material name="red">
        <color rgba="0.8 0 0 1"/>
    </material>
    <material name="green">
        <color rgba="0 0.8 0 1"/>
    </material>
    <material name="purple">
        <color rgba="0.8 0 0.8 1"/>
    </material>

    <gazebo>
        <plugin name="gazebo_ros_control" filename="libgazebo_ros_control.so">
            <robotNamespace>/naro</robotNamespace>
            <robotSimType>gazebo_ros_control/DefaultRobotHWSim</robotSimType>
            <legacyModeNS>true</legacyModeNS>
        </plugin>
    </gazebo>

    <!-- * * * Link Definitions * * * -->
    <link name="dummy_link">
    </link>

    <link name="base_link">
       <inertial>
            <origin xyz="0 0 0" rpy="0 0 0"/>
            <mass value="0.2" />
            <inertia ixx="0.0005726" ixy="0.0" ixz="0.0" iyy="0.0005726" iyz="0.0" izz="0.0002704"/>
        </inertial>
        <collision>
            <origin rpy="0.0 0 0" xyz="0 0 0"/>
            <geometry>
                <cylinder radius="0.052" length="0.162"/>
            </geometry>
        </collision>
        <visual>
            <origin rpy="0.0 0 0" xyz="0 0 0"/>
            <geometry>
                <cylinder radius="0.052" length="0.162"/>
            </geometry>
            <material name="red"/>
        </visual>
    </link>

    <gazebo reference="base_link">
        <kp>1000000.0</kp>
        <kd>1000000.0</kd>
        <mu1>10.0</mu1>
        <mu2>10.0</mu2>
        <material>Gazebo/Red</material>
    </gazebo>
    
    <joint name="dummy_joint" type="fixed">
        <parent link="dummy_link"/>
        <child link="base_link"/>
    </joint>

    <link name="NaroBody_2_link">
        <inertial>
            <origin xyz="0 0 0.0362" rpy="0 0 0"/>
            <mass value="0.2" />
            <inertia ixx="0.000220439071667" ixy="0.0" ixz="0.0" iyy="0.000220439071667" iyz="0.0" izz="0.00026615281"/>
        </inertial>
        <collision>
            <origin xyz="0 0 0.0362" rpy="0 0 0"/>
            <geometry>
                <cylinder radius="0.05159" length="0.0724"/>
            </geometry>
        </collision>
        <visual>
            <origin xyz="0 0 0.0362" rpy="0 0 0"/>
            <geometry>
                <cylinder radius="0.05159" length="0.0724"/>
            </geometry>
            <material name="blue"/>
        </visual>
    </link>
    
    <!-- This is for color and physical properties in Gazebo, color won't work with the material tag in gazebo
    only for URDF coloring -->
    <gazebo reference="NaroBody_2_link">
        <kp>1000000.0</kp>
        <kd>1000000.0</kd>
        <mu1>10.0</mu1>
        <mu2>10.0</mu2>
        <material>Gazebo/Blue</material>
    </gazebo>

    <joint name="NaroBody_1_NaroBody_2_joint" type="revolute">
        <parent link="base_link"/>
        <child link="NaroBody_2_link"/>
        <origin xyz="0 0 0.096" rpy="0 0 0"/>
        <limit lower="-0.2" upper="0.2" effort="10.0" velocity="1.0"/>
        <axis xyz="1 0 0"/>
    </joint>

    <transmission name="tran1">
        <type>transmission_interface/SimpleTransmission</type>
        <joint name="NaroBody_1_NaroBody_2_joint">
            <hardwareInterface>hardware_interface/EffortJointInterface</hardwareInterface>
        </joint>
        <actuator name="motor1">
            <hardwareInterface>hardware_interface/EffortJointInterface</hardwareInterface>
            <mechanicalReduction>1</mechanicalReduction>
        </actuator>
    </transmission>

</robot>