<?xml version="1.0" ?>
<!-- =================================================================================== -->
<!-- |    This document was autogenerated by xacro from robot.xacro                    | -->
<!-- |    EDITING THIS FILE BY HAND IS NOT RECOMMENDED                                 | -->
<!-- =================================================================================== -->
<robot name="vehicle" xmlns:xacro="http://www.ros.org/wiki/xacro">
  <!-- Define algunos colores para ser usados en rviz y Gazebo -->
  <material name="grey">
    <color rgba="0.42 0.42 0.42 1"/>
  </material>
  <material name="dark_grey">
    <color rgba="0.22 0.22 0.22 1"/>
  </material>
  <material name="black">
    <color rgba="0.12 0.12 0.12 1"/>
  </material>
  <material name="blue">
    <color rgba="0.08 0.22 0.48 1"/>
  </material>
  <!-- Controladores ROS para Gazebo -->
  <gazebo>
    <plugin filename="libgazebo_ros_control.so" name="gazebo_ros_control">
      <robotNamespace>/vehicle</robotNamespace>
      <robotSimType>gazebo_ros_control/DefaultRobotHWSim</robotSimType>
      <legacyModeNS>true</legacyModeNS>
    </plugin>
  </gazebo>
  <!-- Define algunos colores para ser usados en rviz y Gazebo -->
  <material name="grey">
    <color rgba="0.42 0.42 0.42 1"/>
  </material>
  <material name="dark_grey">
    <color rgba="0.22 0.22 0.22 1"/>
  </material>
  <material name="black">
    <color rgba="0.12 0.12 0.12 1"/>
  </material>
  <material name="blue">
    <color rgba="0.08 0.22 0.48 1"/>
  </material>
  <!-- Dummy -->
  <link name="dummy_link"/>
  <!-- Chassis -->
  <link name="base_link">
    <inertial>
      <origin rpy="0 0 0" xyz="0 0 0"/>
      <mass value="130"/>
      <inertia ixx="15" ixy="0" ixz="0" iyy="52" iyz="0" izz="66"/>
    </inertial>
    <visual>
      <origin rpy="0 0 0" xyz="0 0 0"/>
      <geometry>
        <box size="2.186 1.162 0.17"/>
      </geometry>
      <material name="blue"/>
    </visual>
    <collision>
      <origin rpy="0 0 0" xyz="0 0 0"/>
      <geometry>
        <box size="2.186 1.162 0.17"/>
      </geometry>
    </collision>
  </link>
  <gazebo reference="base_link">
    <kp value="1000000"/>
    <kd value="1"/>
    <mu1 value="10"/>
    <mu2 value="10"/>
    <visual>
      <material>
        <ambient>0.00 0.16 0.42 1</ambient>
        <diffuse>0.04 0.20 0.46 1</diffuse>
        <specular>0.08 0.24 0.50 1</specular>
      </material>
    </visual>
  </gazebo>
  <joint name="dummy_joint" type="fixed">
    <parent link="dummy_link"/>
    <child link="base_link"/>
  </joint>
  <link name="front_left_wheel_link">
    <inertial>
      <origin rpy="0 0 0" xyz="0 0 0"/>
      <mass value="10"/>
      <inertia ixx="0.2" ixy="0" ixz="0" iyy="0.35" iyz="0" izz="0.2"/>
    </inertial>
    <visual>
      <origin rpy="1.57079632679 0 0" xyz="0 0 0"/>
      <geometry>
        <cylinder length="0.076" radius="0.272"/>
      </geometry>
      <material name="grey"/>
    </visual>
    <collision>
      <origin rpy="1.57079632679 0 0" xyz="0 0 0"/>
      <geometry>
        <cylinder length="0.076" radius="0.272"/>
      </geometry>
    </collision>
  </link>
  <gazebo reference="front_left_wheel_link">
    <kp value="1000000"/>
    <kd value="1"/>
    <mu1 value="10"/>
    <mu2 value="10"/>
    <visual>
      <material>
        <ambient>0.38 0.38 0.38 1</ambient>
        <diffuse>0.42 0.42 0.42 1</diffuse>
        <specular>0.46 0.46 0.46 1</specular>
      </material>
    </visual>
  </gazebo>
  <joint name="front_left_wheel_joint" type="continuous">
    <parent link="base_link"/>
    <child link="front_left_wheel_link"/>
    <origin rpy="0 0 0" xyz="0.621 0.543 0"/>
    <axis xyz="0 1 0"/>
  </joint>
  <transmission name="tran1">
    <type>transmission_interface/SimpleTransmission</type>
    <joint name="front_left_wheel_joint">
      <hardwareInterface>hardware_interface/EffortJointInterface</hardwareInterface>
    </joint>
    <actuator name="motor1">
      <hardwareInterface>hardware_interface/EffortJointInterface</hardwareInterface>
      <mechanicalReduction>1</mechanicalReduction>
    </actuator>
  </transmission>
  <link name="front_right_wheel_link">
    <inertial>
      <origin rpy="0 0 0" xyz="0 0 0"/>
      <mass value="10"/>
      <inertia ixx="0.2" ixy="0" ixz="0" iyy="0.35" iyz="0" izz="0.2"/>
    </inertial>
    <visual>
      <origin rpy="1.57079632679 0 0" xyz="0 0 0"/>
      <geometry>
        <cylinder length="0.076" radius="0.272"/>
      </geometry>
      <material name="grey"/>
    </visual>
    <collision>
      <origin rpy="1.57079632679 0 0" xyz="0 0 0"/>
      <geometry>
        <cylinder length="0.076" radius="0.272"/>
      </geometry>
    </collision>
  </link>
  <gazebo reference="front_right_wheel_link">
    <kp value="1000000"/>
    <kd value="1"/>
    <mu1 value="10"/>
    <mu2 value="10"/>
    <visual>
      <material>
        <ambient>0.38 0.38 0.38 1</ambient>
        <diffuse>0.42 0.42 0.42 1</diffuse>
        <specular>0.46 0.46 0.46 1</specular>
      </material>
    </visual>
  </gazebo>
  <joint name="front_right_wheel_joint" type="continuous">
    <parent link="base_link"/>
    <child link="front_right_wheel_link"/>
    <origin rpy="0 0 0" xyz="0.621 -0.543 0"/>
    <axis xyz="0 1 0"/>
  </joint>
  <transmission name="tran2">
    <type>transmission_interface/SimpleTransmission</type>
    <joint name="front_right_wheel_joint">
      <hardwareInterface>hardware_interface/EffortJointInterface</hardwareInterface>
    </joint>
    <actuator name="motor2">
      <hardwareInterface>hardware_interface/EffortJointInterface</hardwareInterface>
      <mechanicalReduction>1</mechanicalReduction>
    </actuator>
  </transmission>
  <link name="rear_left_wheel_link">
    <inertial>
      <origin rpy="0 0 0" xyz="0 0 0"/>
      <mass value="10"/>
      <inertia ixx="0.2" ixy="0" ixz="0" iyy="0.35" iyz="0" izz="0.2"/>
    </inertial>
    <visual>
      <origin rpy="1.57079632679 0 0" xyz="0 0 0"/>
      <geometry>
        <cylinder length="0.076" radius="0.272"/>
      </geometry>
      <material name="grey"/>
    </visual>
    <collision>
      <origin rpy="1.57079632679 0 0" xyz="0 0 0"/>
      <geometry>
        <cylinder length="0.076" radius="0.272"/>
      </geometry>
    </collision>
  </link>
  <gazebo reference="rear_left_wheel_link">
    <kp value="1000000"/>
    <kd value="1"/>
    <mu1 value="10"/>
    <mu2 value="10"/>
    <visual>
      <material>
        <ambient>0.38 0.38 0.38 1</ambient>
        <diffuse>0.42 0.42 0.42 1</diffuse>
        <specular>0.46 0.46 0.46 1</specular>
      </material>
    </visual>
  </gazebo>
  <joint name="rear_left_wheel_joint" type="continuous">
    <parent link="base_link"/>
    <child link="rear_left_wheel_link"/>
    <origin rpy="0 0 0" xyz="-0.621 0.543 0"/>
    <axis xyz="0 1 0"/>
  </joint>
  <transmission name="tran3">
    <type>transmission_interface/SimpleTransmission</type>
    <joint name="rear_left_wheel_joint">
      <hardwareInterface>hardware_interface/EffortJointInterface</hardwareInterface>
    </joint>
    <actuator name="motor3">
      <hardwareInterface>hardware_interface/EffortJointInterface</hardwareInterface>
      <mechanicalReduction>1</mechanicalReduction>
    </actuator>
  </transmission>
  <link name="rear_right_wheel_link">
    <inertial>
      <origin rpy="0 0 0" xyz="0 0 0"/>
      <mass value="10"/>
      <inertia ixx="0.2" ixy="0" ixz="0" iyy="0.35" iyz="0" izz="0.2"/>
    </inertial>
    <visual>
      <origin rpy="1.57079632679 0 0" xyz="0 0 0"/>
      <geometry>
        <cylinder length="0.076" radius="0.272"/>
      </geometry>
      <material name="grey"/>
    </visual>
    <collision>
      <origin rpy="1.57079632679 0 0" xyz="0 0 0"/>
      <geometry>
        <cylinder length="0.076" radius="0.272"/>
      </geometry>
    </collision>
  </link>
  <gazebo reference="rear_right_wheel_link">
    <kp value="1000000"/>
    <kd value="1"/>
    <mu1 value="10"/>
    <mu2 value="10"/>
    <visual>
      <material>
        <ambient>0.38 0.38 0.38 1</ambient>
        <diffuse>0.42 0.42 0.42 1</diffuse>
        <specular>0.46 0.46 0.46 1</specular>
      </material>
    </visual>
  </gazebo>
  <joint name="rear_right_wheel_joint" type="continuous">
    <parent link="base_link"/>
    <child link="rear_right_wheel_link"/>
    <origin rpy="0 0 0" xyz="-0.621 -0.543 0"/>
    <axis xyz="0 1 0"/>
  </joint>
  <transmission name="tran4">
    <type>transmission_interface/SimpleTransmission</type>
    <joint name="rear_right_wheel_joint">
      <hardwareInterface>hardware_interface/EffortJointInterface</hardwareInterface>
    </joint>
    <actuator name="motor4">
      <hardwareInterface>hardware_interface/EffortJointInterface</hardwareInterface>
      <mechanicalReduction>1</mechanicalReduction>
    </actuator>
  </transmission>
</robot>

